Workbook

Sheet Kapak
A1: Ezine Hibrit RES + Batarya — Finansal Model
A2: Reel 2026 USD · %7 reel WACC · FAST standardına yakın yapı · Ekim 2026
A4: Renk kodu
A5: Mavi yazı, sarı zemin = girdi
A6: Siyah yazı = formül
A7: Python_girdileri = Python modelinden (saatlik dispatch) gelen değerler
A9: İçindekiler
A10: Girdiler | B10: Tüm varsayımlar ve senaryo seçimi (gelir yapısı, fiyat, P50/P90, teşvik, edinim primi)
A11: Python_girdileri | B11: Yıllık üretim ve batarya büyüklükleri (Python dispatch LP'leri), kaynak açıklamalı
A12: Zaman | B12: Zaman çizelgesi (COD girdiden), iskonto, YEKDEM yıllık katılım kararı
A13: Uretim | B13: Seçilen yapı ve üretim durumuna göre yıllık üretim, sistem kesintisi
A14: Gelir | B14: RES ve batarya gelir kalemleri (YEKDEM dönemi ve sonrası)
A15: OPEX | B15: İşletme giderleri, FAVÖK, augmentation/yenileme, söküm
A16: Vergi | B16: Amortisman, 5 yıllık FIFO zarar mahsubu, kurumlar vergisi, KDV (teşvik yoksa)
A17: Borc | B17: DSCR hedefli heykelsi borç, geri ödeme tablosu, DSCR, LLCR
A18: Nakit_akisi | B18: Proje ve öz kaynak nakit akışları
A19: Ozet | B19: NPV, IRR, LCOE, DSCR, geri ödeme, azami edinim primi
A20: Senaryolar | B20: 96 senaryo (48 × v1/düzeltilmiş): Python ve Excel (LibreOffice ile yeniden hesaplanmış) sonuçları
A21: Kontroller | B21: Nakit tutarlılığı, borç sıfırlanması, Python mutabakatı, formül hatası sayımı
A24: Not: Monte Carlo sonuçları (beklenen NPV, P(NPV>0)) bu deterministik modelde yoktur; Ozet sayfasında Python Monte Carlo referansı ayrıca verilir.
A26: Düzeltme notu (Ekim 2026) | B26: v1'de RES sigortası ve arazi kirası hem 35.000 $/MW-yıl'lık O&M'in (Lazard, her şey dahil) içinde hem ayrı kalem olarak sayılıyordu. Düzeltilmiş senaryo Girdiler sayfasından seçilebilir ("Sigorta + arazi çift sayımı"). Baz vaka Monte Carlo: E[NPV] −1,66 → +0,92 M$, karar (b) rafa kaldır → (a) durum tespiti + sınırlı teklif. Ayrıntı: docs/v1_duzeltme_notu.md

Sheet Girdiler
A1: Girdiler
A2: Mavi = girdi. Senaryo seçimi bu sayfadan; değerler config.yaml'dan (kaynaklarıyla).
A4: Girdi | C4: Değer | D4: Birim | E4: Kaynak / not
A5: Senaryo seçimi
A6: Gelir yapısı | C6: YEKDEM nominal | D6: liste | E6: Baz vaka: YEKDEM yıllık opsiyonu (nominal koridor) + tüccar
A7: Fiyat seviyesi | C7: Baz | D7: liste | E7: Düşük 45 / Baz 58 / Yüksek 72 USD/MWh (reel)
A8: Üretim durumu | C8: P50 | D8: liste | E8: P90 = 10 yıllık P90/P50 = 0,94 (Aşama 5)
A9: Yatırım teşvik belgesi | C9: Var | D9: liste | E9: CK 9903: KDV istisnası; yoksa KDV ön finansmanı
A10: Sigorta + arazi çift sayımı (v1 düzeltme notu) | C10: v1 (çift sayımlı) | D10: liste | E10: v1: RES O&M 35.000 $/MW-yıl (Lazard, her şey dahil) + ayrıca RES arazi ve RES sigortası. Düzeltilmiş: bu iki RES kalemi düşülür (docs/v1_duzeltme_notu.md)
A11: Edinim primi (bugünkü değer) | C11: 0 | D11: USD | E11: t = 0'da ödenir; azami prim = primsiz NPV
A12: COD yılı (ticari işletme başlangıcı) | C12: 2030 | D12: yıl | E12: Takvim P50 Kasım 2029 → yıllık modelde 2030 (Python_girdileri bu COD için)
A14: Fiyat seviyeleri
A15: Fiyat seviyesi — Düşük | C15: 45 | D15: USD/MWh | E15: config: fiyat_senaryolari.seviye
A16: Fiyat seviyesi — Baz | C16: 58 | D16: USD/MWh | E16: config: fiyat_senaryolari.seviye
A17: Fiyat seviyesi — Yüksek | C17: 72 | D17: USD/MWh | E17: config: fiyat_senaryolari.seviye
A18: Seçilen fiyat seviyesi L | C18: =IF(Girdiler!$C$7="Düşük",Girdiler!$C$15,IF(Girdiler!$C$7="Yüksek",Girdiler!$C$17,Girdiler!$C$16)) | D18: USD/MWh
A19: Yapı indeksi (1 Tüccar, 2 PPA, 3 YEKDEM nom., 4 YEKDEM end.) | C19: =(Girdiler!$C$6="Tüccar")*1+(Girdiler!$C$6="PPA")*2+(Girdiler!$C$6="YEKDEM nominal")*3+(Girdiler!$C$6="YEKDEM endeksli")*4
A20: Çift sayım düzeltmesi açık mı? (1 = düzeltilmiş) | C20: =IF(Girdiler!$C$10="Düzeltilmiş",1,0)
A21: Senaryo anahtarı (mutabakat) | C21: =Girdiler!$C$6&"|"&Girdiler!$C$7&"|"&Girdiler!$C$8&"|"&Girdiler!$C$9&IF(Girdiler!$C$20=1,"|Düzeltilmiş","")
A23: Tasarım
A24: RES kurulu gücü (14 × 4,2 MW) | C24: 58.8 | D24: MW | E24: Aşama 4 optimizasyonu
A25: Batarya gücü | C25: 30 | D25: MW | E25: Ö1: tam 30 MW SFK rezervi için 2 saat
A26: Batarya enerjisi | C26: 60 | D26: MWh
A27: Şebeke bağlantısı | C27: 50 | D27: MW
A29: CAPEX ve teknik
A30: RES CAPEX | C30: 1150000 | D30: USD/MW | E30: config: teknoloji.res.capex (IRENA/BNEF)
A31: Batarya CAPEX — enerji | C31: 110000 | D31: USD/MWh | E31: config: teknoloji.bess.capex_enerji
A32: Batarya CAPEX — güç | C32: 90000 | D32: USD/MW | E32: config: teknoloji.bess.capex_guc
A33: Şebeke CAPEX | C33: 120000 | D33: USD/MW | E33: config: teknoloji.sebeke.capex
A34: CAPEX takvimi — 1. inşaat yılı | C34: 0.4 | D34: pay | E34: config: proje.capex_takvimi
A35: CAPEX takvimi — 2. inşaat yılı | C35: 0.6 | D35: pay
A36: İşletme ömrü | C36: 30 | D36: yıl
A38: İşletme giderleri
A39: RES sabit O&M | C39: 35000 | D39: USD/MW-yıl | E39: config
A40: RES arazi | C40: 1500 | D40: USD/MW-yıl | E40: config
A41: Batarya O&M (CAPEX'e oran) | C41: 0.025 | D41: oran | E41: config
A42: Sigorta (CAPEX'e oran) | C42: 0.0035 | D42: oran | E42: config
A43: TEİAŞ kapasite bedeli | C43: 3470 | D43: USD/MW-yıl | E43: config
A44: TEİAŞ enerji bedeli | C44: 3.8 | D44: USD/MWh | E44: config
A45: Batarya yıpranma maliyeti | C45: 6 | D45: USD/MWh deşarj | E45: config
...

Sheet Python_girdileri
A1: Python girdileri — saatlik dispatch LP'lerinden yıllık birim büyüklükler (işletme yılı 1–30, COD 2030)
A2: Kaynak: src/08_excel_model.py → src/risk/degerleme.nakit_akislari (X matrisi). Deterministik baz: 10 hava yılı × 2 fiyat şekli ortalaması, kanibalizasyon 'devam' + ortak batarya sürücüsü, baz doyum SFK yolu, beklenen sistem kesintisi. *_q = Σ üretim × birim fiyat şekli (fiyat seviyesi 1 için; gelir = L × *_q), E_* = MWh, yh_a = SFK birimi (gelir = a × yh_a).
A3: Rejimler: T = tüccar dispatch'i (tüccar ve finansal PPA), Y0 = YEKDEM tablosunun katılımsız dilimi, Y1 = YEKDEM'e katılım (deşarj da YEKDEM fiyatından → arbitraj yok). P90: RES çarpanı 0,94. COD değişirse bu takvim bağımlı girdiler kaydırılmaz.
A5: İşletme yılı | B5: Takvim yılı (COD 2030) | C5: SFK fiyat çarpanı a | D5: Beklenen kesinti oranı κ | E5: T_P50_gelir_res_q | F5: T_P50_E_res | G5: T_P50_gelir_d_q | H5: T_P50_E_d | I5: T_P50_yh_a | J5: T_P50_rezerv | K5: T_P50_E_k | L5: T_P50_E_A | M5: T_P90_gelir_res_q | N5: T_P90_E_res | O5: T_P90_gelir_d_q | P5: T_P90_E_d | Q5: T_P90_yh_a | R5: T_P90_rezerv | S5: T_P90_E_k | T5: T_P90_E_A | U5: Y0_P50_gelir_res_q | V5: Y0_P50_E_res | W5: Y0_P50_gelir_d_q | X5: Y0_P50_E_d | Y5: Y0_P50_yh_a | Z5: Y0_P50_rezerv | AA5: Y0_P50_E_k | AB5: Y0_P50_E_A | AC5: Y0_P90_gelir_res_q | AD5: Y0_P90_E_res | AE5: Y0_P90_gelir_d_q | AF5: Y0_P90_E_d | AG5: Y0_P90_yh_a | AH5: Y0_P90_rezerv | AI5: Y0_P90_E_k | AJ5: Y0_P90_E_A | AK5: Y1_P50_gelir_res_q | AL5: Y1_P50_E_res | AM5: Y1_P50_gelir_d_q | AN5: Y1_P50_E_d | AO5: Y1_P50_yh_a | AP5: Y1_P50_rezerv | AQ5: Y1_P50_E_k | AR5: Y1_P50_E_A | AS5: Y1_P90_gelir_res_q | AT5: Y1_P90_E_res | AU5: Y1_P90_gelir_d_q | AV5: Y1_P90_E_d | AW5: Y1_P90_yh_a | AX5: Y1_P90_rezerv | AY5: Y1_P90_E_k | AZ5: Y1_P90_E_A
A6: 1 | B6: 2030 | C6: 0.048463042 | D6: 0.065921494 | E6: 178164.54 | F6: 163164.27 | G6: 27427.28 | H6: 18963 | I6: 7333492.8 | J6: 145260.86 | K6: 9053.8591 | L6: 194014.68 | M6: 168171.94 | N6: 152919.76 | O6: 28127.387 | P6: 19411.708 | Q6: 7220055.2 | R6: 143301.92 | S6: 7141.7344 | T6: 182373.8 | U6: 178164.54 | V6: 163164.27 | W6: 27427.28 | X6: 18963 | Y6: 7333492.8 | Z6: 145260.86 | AA6: 9053.8591 | AB6: 194014.68 | AC6: 168171.94 | AD6: 152919.76 | AE6: 28127.387 | AF6: 19411.708 | AG6: 7220055.2 | AH6: 143301.92 | AI6: 7141.7344 | AJ6: 182373.8 | AK6: 190433.54 | AL6: 190908.3 | AM6: 1760.9393 | AN6: 1562.2085 | AO6: 12166155 | AP6: 253578.96 | AQ6: 1310.7358 | AR6: 194014.68 | AS6: 181791.35 | AT6: 182373.8 | AU6: 2.2217468e-13 | AV6: 1.7833667e-13 | AW6: 12528933 | AX6: 262800 | AY6: 0 | AZ6: 182373.8
A7: 2 | B7: 2031 | C7: 0.048463042 | D7: 0.067981794 | E7: 176980.96 | F7: 161730.9 | G7: 28237.837 | H7: 19330.326 | I7: 7209097.7 | J7: 141220.48 | K7: 9482.9749 | L7: 193432.64 | M7: 166920.78 | N7: 151434.4 | O7: 29000.087 | P7: 19820.005 | Q7: 7089673.5 | R7: 138961.05 | S7: 7610.6656 | T7: 181826.68 | U7: 176980.96 | V7: 161730.9 | W7: 28237.837 | X7: 19330.326 | Y7: 7209097.7 | Z7: 141220.48 | AA7: 9482.9749 | AB7: 193432.64 | AC7: 166920.78 | AD7: 151434.4 | AE7: 29000.087 | AF7: 19820.005 | AG7: 7089673.5 | AH7: 138961.05 | AI7: 7610.6656 | AJ7: 181826.68 | AK7: 189468.47 | AL7: 190481.58 | AM7: 1678.1582 | AN7: 1484.0981 | AO7: 12184294 | AP7: 254040.01 | AQ7: 1245.199 | AR7: 193432.64 | AS7: 180721.13 | AT7: 181826.68 | AU7: 2.1986519e-13 | AV7: 1.655338e-13 | AW7: 12528933 | AX7: 262800 | AY7: 0 | AZ7: 181826.68
A8: 3 | B8: 2032 | C8: 0.048463042 | D8: 0.070038772 | E8: 175815.09 | F8: 160318.96 | G8: 29036.197 | H8: 19693.421 | I8: 7086438.2 | J8: 137233.48 | K8: 9897.2627 | L8: 192852.34 | M8: 165689.95 | N8: 149975.94 | O8: 29854.469 | P8: 20219.268 | Q8: 6962304.8 | R8: 134722.45 | S8: 8064.7232 | T8: 181281.2 | U8: 175815.09 | V8: 160318.96 | W8: 29036.197 | X8: 19693.421 | Y8: 7086438.2 | Z8: 137233.48 | AA8: 9897.2627 | AB8: 192852.34 | AC8: 165689.95 | AD8: 149975.94 | AE8: 29854.469 | AF8: 20219.268 | AG8: 6962304.8 | AH8: 134722.45 | AI8: 8064.7232 | AJ8: 181281.2 | AK8: 188517.66 | AL8: 190056.13 | AM8: 1594.9736 | AN8: 1406.222 | AO8: 12202379 | AP8: 254499.68 | AQ8: 1179.8588 | AR8: 192852.34 | AS8: 179667.76 | AT8: 181281.2 | AU8: 2.1704078e-13 | AV8: 1.5284183e-13 | AW8: 12528933 | AX8: 262800 | AY8: 0 | AZ8: 181281.2
A9: 4 | B9: 2033 | C9: 0.048463042 | D9: 0.072079548 | E9: 174715.88 | F9: 158992.19 | G9: 29778.072 | H9: 20018.716 | I9: 6972932.3 | J9: 133596.22 | K9: 10271.577 | L9: 192273.78 | M9: 164533.16 | N9: 148611.6 | O9: 30641.8 | P9: 20572.539 | Q9: 6845851 | R9: 130904.26 | S9: 8479.1605 | T9: 180737.35 | U9: 174715.88 | V9: 158992.19 | W9: 29778.072 | X9: 20018.716 | Y9: 6972932.3 | Z9: 133596.22 | AA9: 10271.577 | AB9: 192273.78 | AC9: 164533.16 | AD9: 148611.6 | AE9: 30641.8 | AF9: 20572.539 | AG9: 6845851 | AH9: 130904.26 | AI9: 8479.1605 | AJ9: 180737.35 | AK9: 187582.91 | AL9: 189631.96 | AM9: 1511.3891 | AN9: 1328.5795 | AO9: 12220409 | AP9: 254957.97 | AQ9: 1114.7146 | AR9: 192273.78 | AS9: 178632.9 | AT9: 180737.35 | AU9: 2.122534e-13 | AV9: 1.4242998e-13 | AW9: 12528933 | AX9: 262800 | AY9: 0 | AZ9: 180737.35
A10: 5 | B10: 2034 | C10: 0.048463042 | D10: 0.074088829 | E10: 174250.4 | F10: 158523.15 | G10: 29780.836 | H10: 20036.569 | I10: 6971640.2 | J10: 133608.04 | K10: 10143.275 | L10: 191696.96 | M10: 163994.78 | N10: 148107.48 | O10: 30641.897 | P10: 20588.627 | Q10: 6850281.5 | R10: 131049.48 | S10: 8422.5749 | T10: 180195.14 | U10: 174250.4 | V10: 158523.15 | W10: 29780.836 | X10: 20036.569 | Y10: 6971640.2 | Z10: 133608.04 | AA10: 10143.275 | AB10: 191696.96 | AC10: 163994.78 | AD10: 148107.48 | AE10: 30641.897 | AF10: 20588.627 | AG10: 6850281.5 | AH10: 131049.48 | AI10: 8422.5749 | AJ10: 180195.14 | AK10: 187199.72 | AL10: 189209.07 | AM10: 1422.9611 | AN10: 1251.17 | AO10: 12238385 | AP10: 255414.89 | AQ10: 1049.7659 | AR10: 191696.96 | AS10: 178140.07 | AT10: 180195.14 | AU10: 2.0889165e-13 | AV10: 1.3926769e-13 | AW10: 12528933 | AX10: 262800 | AY10: 0 | AZ10: 180195.14
A11: 6 | B11: 2035 | C11: 0.048463042 | D11: 0.076048533 | E11: 173800.83 | F11: 158074.97 | G11: 29768.582 | H11: 20045.056 | I11: 6972789.9 | J11: 133710.23 | K11: 10006.602 | L11: 191121.87 | M11: 163473.35 | N11: 147624.81 | O11: 30625.95 | P11: 20594.645 | Q11: 6857230.1 | R11: 131288.91 | S11: 8357.7361 | T11: 179654.56 | U11: 173800.83 | V11: 158074.97 | W11: 29768.582 | X11: 20045.056 | Y11: 6972789.9 | Z11: 133710.23 | AA11: 10006.602 | AB11: 191121.87 | AC11: 163473.35 | AD11: 147624.81 | AE11: 30625.95 | AF11: 20594.645 | AG11: 6857230.1 | AH11: 131288.91 | AI11: 8357.7361 | AJ11: 179654.56 | AK11: 186822.36 | AL11: 188787.44 | AM11: 1334.8063 | AN11: 1173.9927 | AO11: 12256307 | AP11: 255870.43 | AQ11: 985.01204 | AR11: 191121.87 | AS11: 177653.08 | AT11: 179654.56 | AU11: 2.0523684e-13 | AV11: 1.3659299e-13 | AW11: 12528933 | AX11: 262800 | AY11: 0 | AZ11: 179654.56
A12: 7 | B12: 2036 | C12: 0.048463042 | D12: 0.079514812 | E12: 173284.66 | F12: 157535.15 | G12: 29839.73 | H12: 20085.019 | I12: 6961405 | J12: 133416.19 | K12: 9927.1211 | L12: 190548.5 | M12: 162888.82 | N12: 147051.79 | O12: 30697.767 | P12: 20634.55 | Q12: 6850811.1 | R12: 131103.33 | S12: 8345.9267 | T12: 179115.59 | U12: 173284.66 | V12: 157535.15 | W12: 29839.73 | X12: 20085.019 | Y12: 6961405 | Z12: 133416.19 | AA12: 9927.1211 | AB12: 190548.5 | AC12: 162888.82 | AD12: 147051.79 | AE12: 30697.767 | AF12: 20634.55 | AG12: 6850811.1 | AH12: 131103.33 | AI12: 8345.9267 | AJ12: 179115.59 | AK12: 186377.88 | AL12: 188367.08 | AM12: 1247.4652 | AN12: 1097.0469 | AO12: 12274176 | AP12: 256324.61 | AQ12: 920.45242 | AR12: 190548.5 | AS12: 177100.9 | AT12: 179115.59 | AU12: 2.0105638e-13 | AV12: 1.3349463e-13 | AW12: 12528933 | AX12: 262800 | AY12: 0 | AZ12: 179115.59
A13: 8 | B13: 2037 | C13: 0.048463042 | D13: 0.083119742 | E13: 172782.43 | F13: 157012.89 | G13: 29899.632 | H13: 20116.59 | I13: 6951880.5 | J13: 133195.87 | K13: 9841.4472 | L13: 189976.86 | M13: 162319.42 | N13: 146497.24 | O13: 30757.256 | P13: 20665.234 | Q13: 6846379.2 | R13: 130997.15 | S13: 8327.8667 | T13: 178578.25 | U13: 172782.43 | V13: 157012.89 | W13: 29899.632 | X13: 20116.59 | Y13: 6951880.5 | Z13: 133195.87 | AA13: 9841.4472 | AB13: 189976.86 | AC13: 162319.42 | AD13: 146497.24 | AE13: 30757.256 | AF13: 20665.234 | AG13: 6846379.2 | AH13: 130997.15 | AI13: 8327.8667 | AJ13: 178578.25 | AK13: 185935.46 | AL13: 187947.98 | AM13: 1160.3609 | AN13: 1020.332 | AO13: 12291991 | AP13: 256777.42 | AQ13: 856.08648 | AR13: 189976.86 | AS13: 176551.18 | AT13: 178578.25 | AU13: 1.9660221e-13 | AV13: 1.3095519e-13 | AW13: 12528933 | AX13: 262800 | AY13: 0 | AZ13: 178578.25
A14: 9 | B14: 2038 | C14: 0.048463042 | D14: 0.086868869 | E14: 172282.3 | F14: 156492.88 | G14: 29958.81 | H14: 20147.95 | I14: 6942453.1 | J14: 132978.06 | K14: 9755.4874 | L14: 189406.93 | M14: 161752.23 | N14: 145945.04 | O14: 30815.946 | P14: 20695.653 | Q14: 6842058.3 | R14: 130894.13 | S14: 8309.3646 | T14: 178042.51 | U14: 172282.3 | V14: 156492.88 | W14: 29958.81 | X14: 20147.95 | Y14: 6942453.1 | Z14: 132978.06 | AA14: 9755.4874 | AB14: 189406.93 | AC14: 161752.23 | AD14: 145945.04 | AE14: 30815.946 | AF14: 20695.653 | AG14: 6842058.3 | AH14: 130894.13 | AI14: 8309.3646 | AJ14: 178042.51 | AK14: 185495.05 | AL14: 187530.13 | AM14: 1073.4944 | AN14: 943.84717 | AO14: 12309752 | AP14: 257228.88 | AQ14: 791.91364 | AR14: 189406.93 | AS14: 176003.86 | AT14: 178042.51 | AU14: 1.9219693e-13 | AV14: 1.2842625e-13 | AW14: 12528933 | AX14: 262800 | AY14: 0 | AZ14: 178042.51
A15: 10 | B15: 2039 | C15: 0.048463042 | D15: 0.090767961 | E15: 171784.24 | F15: 155975.07 | G15: 30017.286 | H15: 20179.103 | I15: 6933120.3 | J15: 132762.7 | K15: 9669.2656 | L15: 188838.71 | M15: 161187.21 | N15: 145395.17 | O15: 30873.865 | P15: 20725.814 | Q15: 6837844.1 | R15: 130794.13 | S15: 8290.4427 | T15: 177508.38 | U15: 171784.24 | V15: 155975.07 | W15: 30017.286 | X15: 20179.103 | Y15: 6933120.3 | Z15: 132762.7 | AA15: 9669.2656 | AB15: 188838.71 | AC15: 161187.21 | AD15: 145395.17 | AE15: 30873.865 | AF15: 20725.814 | AG15: 6837844.1 | AH15: 130794.13 | AI15: 8290.4427 | AJ15: 177508.38 | AK15: 185056.64 | AL15: 187113.54 | AM15: 986.86622 | AN15: 867.59183 | AO15: 12327460 | AP15: 257678.98 | AQ15: 727.93332 | AR15: 188838.71 | AS15: 175458.91 | AT15: 177508.38 | AU15: 1.878385e-13 | AV15: 1.2590747e-13 | AW15: 12528933 | AX15: 262800 | AY15: 0 | AZ15: 177508.38
A16: 11 | B16: 2040 | C16: 0.048463042 | D16: 0.094823017 | E16: 171288.2 | F16: 155459.44 | G16: 30075.08 | H16: 20210.052 | I16: 6923879.8 | J16: 132549.74 | K16: 9582.8046 | L16: 188272.19 | M16: 160624.33 | N16: 144847.58 | O16: 30931.035 | P16: 20755.725 | Q16: 6833732.7 | R16: 130697.04 | S16: 8271.1224 | T16: 176975.86 | U16: 171288.2 | V16: 155459.44 | W16: 30075.08 | X16: 20210.052 | Y16: 6923879.8 | Z16: 132549.74 | AA16: 9582.8046 | AB16: 188272.19 | AC16: 160624.33 | AD16: 144847.58 | AE16: 30931.035 | AF16: 20755.725 | AG16: 6833732.7 | AH16: 130697.04 | AI16: 8271.1224 | AJ16: 176975.86 | AK16: 184620.19 | AL16: 186698.2 | AM16: 900.47683 | AN16: 791.56525 | AO16: 12345115 | AP16: 258127.73 | AQ16: 664.14494 | AR16: 188272.19 | AS16: 174916.3 | AT16: 176975.86 | AU16: 1.8352502e-13 | AV16: 1.2339852e-13 | AW16: 12528933 | AX16: 262800 | AY16: 0 | AZ16: 176975.86
A17: 12 | B17: 2041 | C17: 0.048463042 | D17: 0.099040275 | E17: 170794.16 | F17: 154945.96 | G17: 30132.213 | H17: 20240.803 | I17: 6914729.2 | J17: 132339.1 | K17: 9496.1262 | L17: 187707.37 | M17: 160063.57 | N17: 144302.25 | O17: 30987.482 | P17: 20785.393 | Q17: 6829720.3 | R17: 130602.75 | S17: 8251.424 | T17: 176444.93 | U17: 170794.16 | V17: 154945.96 | W17: 30132.213 | X17: 20240.803 | Y17: 6914729.2 | Z17: 132339.1 | AA17: 9496.1262 | AB17: 187707.37 | AC17: 160063.57 | AD17: 144302.25 | AE17: 30987.482 | AF17: 20785.393 | AG17: 6829720.3 | AH17: 130602.75 | AI17: 8251.424 | AJ17: 176444.93 | AK17: 184185.67 | AL17: 186284.1 | AM17: 814.32671 | AN17: 715.76675 | AO17: 12362717 | AP17: 258575.14 | AQ17: 600.54792 | AR17: 187707.37 | AS17: 174375.99 | AT17: 176444.93 | AU17: 1.7925466e-13 | AV17: 1.208991e-13 | AW17: 12528933 | AX17: 262800 | AY17: 0 | AZ17: 176444.93
... A35: 30 | B35: 2059 | C35: 0.048463042 | D35: 0.21151973 | E35: 161383.58 | F35: 145506.45 | G35: 31076.433 | H35: 20766.068 | I35: 6805330.4 | J35: 129863.03 | K35: 8450.066 | L35: 177825.56 | M35: 150307.51 | N35: 134840.04 | O35: 31902.366 | P35: 21284.582 | Q35: 6770836.5 | R35: 129279.95 | S35: 7850.9523 | T35: 167156.02 | U35: 161383.58 | V35: 145506.45 | W35: 31076.433 | X35: 20766.068 | Y35: 6805330.4 | Z35: 129863.03 | AA35: 8450.066 | AB35: 177825.56 | AC35: 150307.51 | AD35: 134840.04 | AE35: 31902.366 | AF35: 21284.582 | AG35: 6770836.5 | AH35: 129279.95 | AI35: 7850.9523 | AJ35: 167156.02 | AK35: 175541.89 | AL35: 177825.56 | AM35: 1.8673557e-13 | AN35: 1.3007553e-13 | AO35: 12528933 | AP35: 262800 | AQ35: 0 | AR35: 177825.56 | AS35: 165009.38 | AT35: 167156.02 | AU35: 1.0814041e-13 | AV35: 7.7291204e-14 | AW35: 12528933 | AX35: 262800 | AY35: 0 | AZ35: 167156.02

Sheet Zaman
A1: Zaman çizelgesi ve YEKDEM yıllık katılım kararı
A4: Kalem | B4: Birim | C4: Not / kaynak | D4: Toplam / değer | E4: t0 (bugün) | F4: 2026 | G4: 2027 | H4: 2028 | I4: 2029 | J4: 2030 | K4: 2031 | L4: 2032 | M4: 2033 | N4: 2034 | O4: 2035 | P4: 2036 | Q4: 2037 | R4: 2038 | S4: 2039 | T4: 2040 | U4: 2041 | V4: 2042 | W4: 2043 | X4: 2044 | Y4: 2045 | Z4: 2046 | AA4: 2047 | AB4: 2048 | AC4: 2049 | AD4: 2050 | AE4: 2051 | AF4: 2052 | AG4: 2053 | AH4: 2054 | AI4: 2055 | AJ4: 2056 | AK4: 2057 | AL4: 2058 | AM4: 2059 | AN4: 2060 | AO4: 2061 | AP4: 2062 | AQ4: 2063 | AR4: 2064
A6: Takvim yılı | B6: yıl | E6: 2025 | F6: 2026 | G6: 2027 | H6: 2028 | I6: 2029 | J6: 2030 | K6: 2031 | L6: 2032 | M6: 2033 | N6: 2034 | O6: 2035 | P6: 2036 | Q6: 2037 | R6: 2038 | S6: 2039 | T6: 2040 | U6: 2041 | V6: 2042 | W6: 2043 | X6: 2044 | Y6: 2045 | Z6: 2046 | AA6: 2047 | AB6: 2048 | AC6: 2049 | AD6: 2050 | AE6: 2051 | AF6: 2052 | AG6: 2053 | AH6: 2054 | AI6: 2055 | AJ6: 2056 | AK6: 2057 | AL6: 2058 | AM6: 2059 | AN6: 2060 | AO6: 2061 | AP6: 2062 | AQ6: 2063 | AR6: 2064
A7: İskonto dönemi t | E7: 0 | F7: 1 | G7: 2 | H7: 3 | I7: 4 | J7: 5 | K7: 6 | L7: 7 | M7: 8 | N7: 9 | O7: 10 | P7: 11 | Q7: 12 | R7: 13 | S7: 14 | T7: 15 | U7: 16 | V7: 17 | W7: 18 | X7: 19 | Y7: 20 | Z7: 21 | AA7: 22 | AB7: 23 | AC7: 24 | AD7: 25 | AE7: 26 | AF7: 27 | AG7: 28 | AH7: 29 | AI7: 30 | AJ7: 31 | AK7: 32 | AL7: 33 | AM7: 34 | AN7: 35 | AO7: 36 | AP7: 37 | AQ7: 38 | AR7: 39
A8: İnşaat CAPEX payı | B8: pay | D8: =SUM(F8:AR8) | E8: 0 | F8: =IF('Zaman'!F6=Girdiler!$C$12-2,Girdiler!$C$34,IF('Zaman'!F6=Girdiler!$C$12-1,Girdiler!$C$35,0)) | G8: =IF('Zaman'!G6=Girdiler!$C$12-2,Girdiler!$C$34,IF('Zaman'!G6=Girdiler!$C$12-1,Girdiler!$C$35,0)) | H8: =IF('Zaman'!H6=Girdiler!$C$12-2,Girdiler!$C$34,IF('Zaman'!H6=Girdiler!$C$12-1,Girdiler!$C$35,0)) | I8: =IF('Zaman'!I6=Girdiler!$C$12-2,Girdiler!$C$34,IF('Zaman'!I6=Girdiler!$C$12-1,Girdiler!$C$35,0)) | J8: =IF('Zaman'!J6=Girdiler!$C$12-2,Girdiler!$C$34,IF('Zaman'!J6=Girdiler!$C$12-1,Girdiler!$C$35,0)) | K8: =IF('Zaman'!K6=Girdiler!$C$12-2,Girdiler!$C$34,IF('Zaman'!K6=Girdiler!$C$12-1,Girdiler!$C$35,0)) | L8: =IF('Zaman'!L6=Girdiler!$C$12-2,Girdiler!$C$34,IF('Zaman'!L6=Girdiler!$C$12-1,Girdiler!$C$35,0)) | M8: =IF('Zaman'!M6=Girdiler!$C$12-2,Girdiler!$C$34,IF('Zaman'!M6=Girdiler!$C$12-1,Girdiler!$C$35,0)) | ... AR8: =IF('Zaman'!AR6=Girdiler!$C$12-2,Girdiler!$C$34,IF('Zaman'!AR6=Girdiler!$C$12-1,Girdiler!$C$35,0))
A9: İşletme yılı k | E9: 0 | F9: =IF(AND('Zaman'!F6>=Girdiler!$C$12,'Zaman'!F6<Girdiler!$C$12+Girdiler!$C$36),'Zaman'!F6-Girdiler!$C$12+1,0) | G9: =IF(AND('Zaman'!G6>=Girdiler!$C$12,'Zaman'!G6<Girdiler!$C$12+Girdiler!$C$36),'Zaman'!G6-Girdiler!$C$12+1,0) | H9: =IF(AND('Zaman'!H6>=Girdiler!$C$12,'Zaman'!H6<Girdiler!$C$12+Girdiler!$C$36),'Zaman'!H6-Girdiler!$C$12+1,0) | I9: =IF(AND('Zaman'!I6>=Girdiler!$C$12,'Zaman'!I6<Girdiler!$C$12+Girdiler!$C$36),'Zaman'!I6-Girdiler!$C$12+1,0) | J9: =IF(AND('Zaman'!J6>=Girdiler!$C$12,'Zaman'!J6<Girdiler!$C$12+Girdiler!$C$36),'Zaman'!J6-Girdiler!$C$12+1,0) | K9: =IF(AND('Zaman'!K6>=Girdiler!$C$12,'Zaman'!K6<Girdiler!$C$12+Girdiler!$C$36),'Zaman'!K6-Girdiler!$C$12+1,0) | L9: =IF(AND('Zaman'!L6>=Girdiler!$C$12,'Zaman'!L6<Girdiler!$C$12+Girdiler!$C$36),'Zaman'!L6-Girdiler!$C$12+1,0) | M9: =IF(AND('Zaman'!M6>=Girdiler!$C$12,'Zaman'!M6<Girdiler!$C$12+Girdiler!$C$36),'Zaman'!M6-Girdiler!$C$12+1,0) | ... AR9: =IF(AND('Zaman'!AR6>=Girdiler!$C$12,'Zaman'!AR6<Girdiler!$C$12+Girdiler!$C$36),'Zaman'!AR6-Girdiler!$C$12+1,0)
A10: İskonto faktörü (1 + WACC)^−t | E10: 1 | F10: =1/(1+Girdiler!$C$72)^'Zaman'!F7 | G10: =1/(1+Girdiler!$C$72)^'Zaman'!G7 | H10: =1/(1+Girdiler!$C$72)^'Zaman'!H7 | I10: =1/(1+Girdiler!$C$72)^'Zaman'!I7 | J10: =1/(1+Girdiler!$C$72)^'Zaman'!J7 | K10: =1/(1+Girdiler!$C$72)^'Zaman'!K7 | L10: =1/(1+Girdiler!$C$72)^'Zaman'!L7 | M10: =1/(1+Girdiler!$C$72)^'Zaman'!M7 | ... AR10: =1/(1+Girdiler!$C$72)^'Zaman'!AR7
A11: Enflasyon endeksi (1 + π)^(2 + k) | E11: 0 | F11: =IF('Zaman'!F9>0,(1+Girdiler!$C$73)^(2+'Zaman'!F9),0) | G11: =IF('Zaman'!G9>0,(1+Girdiler!$C$73)^(2+'Zaman'!G9),0) | H11: =IF('Zaman'!H9>0,(1+Girdiler!$C$73)^(2+'Zaman'!H9),0) | I11: =IF('Zaman'!I9>0,(1+Girdiler!$C$73)^(2+'Zaman'!I9),0) | J11: =IF('Zaman'!J9>0,(1+Girdiler!$C$73)^(2+'Zaman'!J9),0) | K11: =IF('Zaman'!K9>0,(1+Girdiler!$C$73)^(2+'Zaman'!K9),0) | L11: =IF('Zaman'!L9>0,(1+Girdiler!$C$73)^(2+'Zaman'!L9),0) | M11: =IF('Zaman'!M9>0,(1+Girdiler!$C$73)^(2+'Zaman'!M9),0) | ... AR11: =IF('Zaman'!AR9>0,(1+Girdiler!$C$73)^(2+'Zaman'!AR9),0)
A12: LCOE iskontosu (inşaat başından) | E12: 0 | F12: =IF('Zaman'!F6>=Girdiler!$C$12-2,1/(1+Girdiler!$C$72)^('Zaman'!F6-(Girdiler!$C$12-2)+1),0) | G12: =IF('Zaman'!G6>=Girdiler!$C$12-2,1/(1+Girdiler!$C$72)^('Zaman'!G6-(Girdiler!$C$12-2)+1),0) | H12: =IF('Zaman'!H6>=Girdiler!$C$12-2,1/(1+Girdiler!$C$72)^('Zaman'!H6-(Girdiler!$C$12-2)+1),0) | I12: =IF('Zaman'!I6>=Girdiler!$C$12-2,1/(1+Girdiler!$C$72)^('Zaman'!I6-(Girdiler!$C$12-2)+1),0) | J12: =IF('Zaman'!J6>=Girdiler!$C$12-2,1/(1+Girdiler!$C$72)^('Zaman'!J6-(Girdiler!$C$12-2)+1),0) | K12: =IF('Zaman'!K6>=Girdiler!$C$12-2,1/(1+Girdiler!$C$72)^('Zaman'!K6-(Girdiler!$C$12-2)+1),0) | L12: =IF('Zaman'!L6>=Girdiler!$C$12-2,1/(1+Girdiler!$C$72)^('Zaman'!L6-(Girdiler!$C$12-2)+1),0) | M12: =IF('Zaman'!M6>=Girdiler!$C$12-2,1/(1+Girdiler!$C$72)^('Zaman'!M6-(Girdiler!$C$12-2)+1),0) | ... AR12: =IF('Zaman'!AR6>=Girdiler!$C$12-2,1/(1+Girdiler!$C$72)^('Zaman'!AR6-(Girdiler!$C$12-2)+1),0)
A13: Python girdisi var mı (1 ≤ k ≤ 30) | E13: 0 | F13: =IF(AND('Zaman'!F9>=1,'Zaman'!F9<=30),1,0) | G13: =IF(AND('Zaman'!G9>=1,'Zaman'!G9<=30),1,0) | H13: =IF(AND('Zaman'!H9>=1,'Zaman'!H9<=30),1,0) | I13: =IF(AND('Zaman'!I9>=1,'Zaman'!I9<=30),1,0) | J13: =IF(AND('Zaman'!J9>=1,'Zaman'!J9<=30),1,0) | K13: =IF(AND('Zaman'!K9>=1,'Zaman'!K9<=30),1,0) | L13: =IF(AND('Zaman'!L9>=1,'Zaman'!L9<=30),1,0) | M13: =IF(AND('Zaman'!M9>=1,'Zaman'!M9<=30),1,0) | ... AR13: =IF(AND('Zaman'!AR9>=1,'Zaman'!AR9<=30),1,0)
A14: YEKDEM reel fiyatı | B14: USD/MWh | C14: Nominal koridor reel olarak aşınır; endeksli varsayımda sabit | E14: 0 | F14: =IF(Girdiler!$C$19=4,Girdiler!$C$67*10,Girdiler!$C$67*10/(1+Girdiler!$C$73)^('Zaman'!F6-2026)) | G14: =IF(Girdiler!$C$19=4,Girdiler!$C$67*10,Girdiler!$C$67*10/(1+Girdiler!$C$73)^('Zaman'!G6-2026)) | H14: =IF(Girdiler!$C$19=4,Girdiler!$C$67*10,Girdiler!$C$67*10/(1+Girdiler!$C$73)^('Zaman'!H6-2026)) | I14: =IF(Girdiler!$C$19=4,Girdiler!$C$67*10,Girdiler!$C$67*10/(1+Girdiler!$C$73)^('Zaman'!I6-2026)) | J14: =IF(Girdiler!$C$19=4,Girdiler!$C$67*10,Girdiler!$C$67*10/(1+Girdiler!$C$73)^('Zaman'!J6-2026)) | K14: =IF(Girdiler!$C$19=4,Girdiler!$C$67*10,Girdiler!$C$67*10/(1+Girdiler!$C$73)^('Zaman'!K6-2026)) | L14: =IF(Girdiler!$C$19=4,Girdiler!$C$67*10,Girdiler!$C$67*10/(1+Girdiler!$C$73)^('Zaman'!L6-2026)) | M14: =IF(Girdiler!$C$19=4,Girdiler!$C$67*10,Girdiler!$C$67*10/(1+Girdiler!$C$73)^('Zaman'!M6-2026)) | ... AR14: =IF(Girdiler!$C$19=4,Girdiler!$C$67*10,Girdiler!$C$67*10/(1+Girdiler!$C$73)^('Zaman'!AR6-2026))
A15: YEKDEM'e katılım (karar 30 Kasım t−1) | B15: 0/1 | C15: Katıl ⇔ YEKDEM reel > eşik × beklenen PTF (deterministik: L) | D15: =SUM(F15:AR15) | E15: 0 | F15: =IF(AND(Girdiler!$C$91=1,'Zaman'!F9>=1,'Zaman'!F9<=Girdiler!$C$68,'Zaman'!F14>Girdiler!$C$69*Girdiler!$C$18),1,0) | G15: =IF(AND(Girdiler!$C$91=1,'Zaman'!G9>=1,'Zaman'!G9<=Girdiler!$C$68,'Zaman'!G14>Girdiler!$C$69*Girdiler!$C$18),1,0) | H15: =IF(AND(Girdiler!$C$91=1,'Zaman'!H9>=1,'Zaman'!H9<=Girdiler!$C$68,'Zaman'!H14>Girdiler!$C$69*Girdiler!$C$18),1,0) | I15: =IF(AND(Girdiler!$C$91=1,'Zaman'!I9>=1,'Zaman'!I9<=Girdiler!$C$68,'Zaman'!I14>Girdiler!$C$69*Girdiler!$C$18),1,0) | J15: =IF(AND(Girdiler!$C$91=1,'Zaman'!J9>=1,'Zaman'!J9<=Girdiler!$C$68,'Zaman'!J14>Girdiler!$C$69*Girdiler!$C$18),1,0) | K15: =IF(AND(Girdiler!$C$91=1,'Zaman'!K9>=1,'Zaman'!K9<=Girdiler!$C$68,'Zaman'!K14>Girdiler!$C$69*Girdiler!$C$18),1,0) | L15: =IF(AND(Girdiler!$C$91=1,'Zaman'!L9>=1,'Zaman'!L9<=Girdiler!$C$68,'Zaman'!L14>Girdiler!$C$69*Girdiler!$C$18),1,0) | M15: =IF(AND(Girdiler!$C$91=1,'Zaman'!M9>=1,'Zaman'!M9<=Girdiler!$C$68,'Zaman'!M14>Girdiler!$C$69*Girdiler!$C$18),1,0) | ... AR15: =IF(AND(Girdiler!$C$91=1,'Zaman'!AR9>=1,'Zaman'!AR9<=Girdiler!$C$68,'Zaman'!AR14>Girdiler!$C$69*Girdiler!$C$18),1,0)
A16: Sözleşmeli pay φ | E16: 0 | F16: =IF(Girdiler!$C$19=2,IF(AND('Zaman'!F9>=1,'Zaman'!F9<=Girdiler!$C$65),Girdiler!$C$64,0),'Zaman'!F15) | G16: =IF(Girdiler!$C$19=2,IF(AND('Zaman'!G9>=1,'Zaman'!G9<=Girdiler!$C$65),Girdiler!$C$64,0),'Zaman'!G15) | H16: =IF(Girdiler!$C$19=2,IF(AND('Zaman'!H9>=1,'Zaman'!H9<=Girdiler!$C$65),Girdiler!$C$64,0),'Zaman'!H15) | I16: =IF(Girdiler!$C$19=2,IF(AND('Zaman'!I9>=1,'Zaman'!I9<=Girdiler!$C$65),Girdiler!$C$64,0),'Zaman'!I15) | J16: =IF(Girdiler!$C$19=2,IF(AND('Zaman'!J9>=1,'Zaman'!J9<=Girdiler!$C$65),Girdiler!$C$64,0),'Zaman'!J15) | K16: =IF(Girdiler!$C$19=2,IF(AND('Zaman'!K9>=1,'Zaman'!K9<=Girdiler!$C$65),Girdiler!$C$64,0),'Zaman'!K15) | L16: =IF(Girdiler!$C$19=2,IF(AND('Zaman'!L9>=1,'Zaman'!L9<=Girdiler!$C$65),Girdiler!$C$64,0),'Zaman'!L15) | M16: =IF(Girdiler!$C$19=2,IF(AND('Zaman'!M9>=1,'Zaman'!M9<=Girdiler!$C$65),Girdiler!$C$64,0),'Zaman'!M15) | ... AR16: =IF(Girdiler!$C$19=2,IF(AND('Zaman'!AR9>=1,'Zaman'!AR9<=Girdiler!$C$65),Girdiler!$C$64,0),'Zaman'!AR15)
A17: Sözleşmeli fiyat (PPA / YEKDEM) | B17: USD/MWh | E17: 0 | F17: =IF(Girdiler!$C$19=2,Girdiler!$C$66,'Zaman'!F14) | G17: =IF(Girdiler!$C$19=2,Girdiler!$C$66,'Zaman'!G14) | H17: =IF(Girdiler!$C$19=2,Girdiler!$C$66,'Zaman'!H14) | I17: =IF(Girdiler!$C$19=2,Girdiler!$C$66,'Zaman'!I14) | J17: =IF(Girdiler!$C$19=2,Girdiler!$C$66,'Zaman'!J14) | K17: =IF(Girdiler!$C$19=2,Girdiler!$C$66,'Zaman'!K14) | L17: =IF(Girdiler!$C$19=2,Girdiler!$C$66,'Zaman'!L14) | M17: =IF(Girdiler!$C$19=2,Girdiler!$C$66,'Zaman'!M14) | ... AR17: =IF(Girdiler!$C$19=2,Girdiler!$C$66,'Zaman'!AR14)

Sheet Uretim
A1: Üretim ve sistem kesintisi
A4: Kalem | B4: Birim | C4: Not / kaynak | D4: Toplam / değer | E4: t0 (bugün) | F4: 2026 | G4: 2027 | H4: 2028 | I4: 2029 | J4: 2030 | K4: 2031 | L4: 2032 | M4: 2033 | N4: 2034 | O4: 2035 | P4: 2036 | Q4: 2037 | R4: 2038 | S4: 2039 | T4: 2040 | U4: 2041 | V4: 2042 | W4: 2043 | X4: 2044 | Y4: 2045 | Z4: 2046 | AA4: 2047 | AB4: 2048 | AC4: 2049 | AD4: 2050 | AE4: 2051 | AF4: 2052 | AG4: 2053 | AH4: 2054 | AI4: 2055 | AJ4: 2056 | AK4: 2057 | AL4: 2058 | AM4: 2059 | AN4: 2060 | AO4: 2061 | AP4: 2062 | AQ4: 2063 | AR4: 2064
A7: — Blok: seçilen üretim durumu —
A8: gelir_res_q | B8: birim | C8: Python_girdileri (rejim: katılıma göre Y1/Y0, aksi T) | D8: =SUM(F8:AR8) | E8: 0 | F8: =IF('Zaman'!F13=1,IF(Girdiler!$C$91=1,IF('Zaman'!F15=1,IF(Girdiler!$C$8="P90",INDEX(Python_girdileri!$AS$6:$AS$35,'Zaman'!F9),INDEX(Python_girdileri!$AK$6:$AK$35,'Zaman'!F9)),IF(Girdiler!$C$8="P90",INDEX(Python_girdileri!$AC$6:$AC$35,'Zaman'!F9),INDEX(Python_girdileri!$U$6:$U$35,'Zaman'!F9))),IF(Girdiler!$C$8="P90",INDEX(Python_girdileri!$M$6:$M$35,'Zaman'!F9),INDEX(Python_girdileri!$E$6:$E$35,'Zaman'!F9))),0) | G8: =IF('Zaman'!G13=1,IF(Girdiler!$C$91=1,IF('Zaman'!G15=1,IF(Girdiler!$C$8="P90",INDEX(Python_girdileri!$AS$6:$AS$35,'Zaman'!G9),INDEX(Python_girdileri!$AK$6:$AK$35,'Zaman'!G9)),IF(Girdiler!$C$8="P90",INDEX(Python_girdileri!$AC$6:$AC$35,'Zaman'!G9),INDEX(Python_girdileri!$U$6:$U$35,'Zaman'!G9))),IF(Girdiler!$C$8="P90",INDEX(Python_girdileri!$M$6:$M$35,'Zaman'!G9),INDEX(Python_girdileri!$E$6:$E$35,'Zaman'!G9))),0) | H8: =IF('Zaman'!H13=1,IF(Girdiler!$C$91=1,IF('Zaman'!H15=1,IF(Girdiler!$C$8="P90",INDEX(Python_girdileri!$AS$6:$AS$35,'Zaman'!H9),INDEX(Python_girdileri!$AK$6:$AK$35,'Zaman'!H9)),IF(Girdiler!$C$8="P90",INDEX(Python_girdileri!$AC$6:$AC$35,'Zaman'!H9),INDEX(Python_girdileri!$U$6:$U$35,'Zaman'!H9))),IF(Girdiler!$C$8="P90",INDEX(Python_girdileri!$M$6:$M$35,'Zaman'!H9),INDEX(Python_girdileri!$E$6:$E$35,'Zaman'!H9))),0) | I8: =IF('Zaman'!I13=1,IF(Girdiler!$C$91=1,IF('Zaman'!I15=1,IF(Girdiler!$C$8="P90",INDEX(Python_girdileri!$AS$6:$AS$35,'Zaman'!I9),INDEX(Python_girdileri!$AK$6:$AK$35,'Zaman'!I9)),IF(Girdiler!$C$8="P90",INDEX(Python_girdileri!$AC$6:$AC$35,'Zaman'!I9),INDEX(Python_girdileri!$U$6:$U$35,'Zaman'!I9))),IF(Girdiler!$C$8="P90",INDEX(Python_girdileri!$M$6:$M$35,'Zaman'!I9),INDEX(Python_girdileri!$E$6:$E$35,'Zaman'!I9))),0) | J8: =IF('Zaman'!J13=1,IF(Girdiler!$C$91=1,IF('Zaman'!J15=1,IF(Girdiler!$C$8="P90",INDEX(Python_girdileri!$AS$6:$AS$35,'Zaman'!J9),INDEX(Python_girdileri!$AK$6:$AK$35,'Zaman'!J9)),IF(Girdiler!$C$8="P90",INDEX(Python_girdileri!$AC$6:$AC$35,'Zaman'!J9),INDEX(Python_girdileri!$U$6:$U$35,'Zaman'!J9))),IF(Girdiler!$C$8="P90",INDEX(Python_girdileri!$M$6:$M$35,'Zaman'!J9),INDEX(Python_girdileri!$E$6:$E$35,'Zaman'!J9))),0) | K8: =IF('Zaman'!K13=1,IF(Girdiler!$C$91=1,IF('Zaman'!K15=1,IF(Girdiler!$C$8="P90",INDEX(Python_girdileri!$AS$6:$AS$35,'Zaman'!K9),INDEX(Python_girdileri!$AK$6:$AK$35,'Zaman'!K9)),IF(Girdiler!$C$8="P90",INDEX(Python_girdileri!$AC$6:$AC$35,'Zaman'!K9),INDEX(Python_girdileri!$U$6:$U$35,'Zaman'!K9))),IF(Girdiler!$C$8="P90",INDEX(Python_girdileri!$M$6:$M$35,'Zaman'!K9),INDEX(Python_girdileri!$E$6:$E$35,'Zaman'!K9))),0) | L8: =IF('Zaman'!L13=1,IF(Girdiler!$C$91=1,IF('Zaman'!L15=1,IF(Girdiler!$C$8="P90",INDEX(Python_girdileri!$AS$6:$AS$35,'Zaman'!L9),INDEX(Python_girdileri!$AK$6:$AK$35,'Zaman'!L9)),IF(Girdiler!$C$8="P90",INDEX(Python_girdileri!$AC$6:$AC$35,'Zaman'!L9),INDEX(Python_girdileri!$U$6:$U$35,'Zaman'!L9))),IF(Girdiler!$C$8="P90",INDEX(Python_girdileri!$M$6:$M$35,'Zaman'!L9),INDEX(Python_girdileri!$E$6:$E$35,'Zaman'!L9))),0) | M8: =IF('Zaman'!M13=1,IF(Girdiler!$C$91=1,IF('Zaman'!M15=1,IF(Girdiler!$C$8="P90",INDEX(Python_girdileri!$AS$6:$AS$35,'Zaman'!M9),INDEX(Python_girdileri!$AK$6:$AK$35,'Zaman'!M9)),IF(Girdiler!$C$8="P90",INDEX(Python_girdileri!$AC$6:$AC$35,'Zaman'!M9),INDEX(Python_girdileri!$U$6:$U$35,'Zaman'!M9))),IF(Girdiler!$C$8="P90",INDEX(Python_girdileri!$M$6:$M$35,'Zaman'!M9),INDEX(Python_girdileri!$E$6:$E$35,'Zaman'!M9))),0) | ... AR8: =IF('Zaman'!AR13=1,IF(Girdiler!$C$91=1,IF('Zaman'!AR15=1,IF(Girdiler!$C$8="P90",INDEX(Python_girdileri!$AS$6:$AS$35,'Zaman'!AR9),INDEX(Python_girdileri!$AK$6:$AK$35,'Zaman'!AR9)),IF(Girdiler!$C$8="P90",INDEX(Python_girdileri!$AC$6:$AC$35,'Zaman'!AR9),INDEX(Python_girdileri!$U$6:$U$35,'Zaman'!AR9))),IF(Girdiler!$C$8="P90",INDEX(Python_girdileri!$M$6:$M$35,'Zaman'!AR9),INDEX(Python_girdileri!$E$6:$E$35,'Zaman'!AR9))),0)
A9: E_res | B9: MWh | C9: Python_girdileri (rejim: katılıma göre Y1/Y0, aksi T) | D9: =SUM(F9:AR9) | E9: 0 | F9: =IF('Zaman'!F13=1,IF(Girdiler!$C$91=1,IF('Zaman'!F15=1,IF(Girdiler!$C$8="P90",INDEX(Python_girdileri!$AT$6:$AT$35,'Zaman'!F9),INDEX(Python_girdileri!$AL$6:$AL$35,'Zaman'!F9)),IF(Girdiler!$C$8="P90",INDEX(Python_girdileri!$AD$6:$AD$35,'Zaman'!F9),INDEX(Python_girdileri!$V$6:$V$35,'Zaman'!F9))),IF(Girdiler!$C$8="P90",INDEX(Python_girdileri!$N$6:$N$35,'Zaman'!F9),INDEX(Python_girdileri!$F$6:$F$35,'Zaman'!F9))),0) | G9: =IF('Zaman'!G13=1,IF(Girdiler!$C$91=1,IF('Zaman'!G15=1,IF(Girdiler!$C$8="P90",INDEX(Python_girdileri!$AT$6:$AT$35,'Zaman'!G9),INDEX(Python_girdileri!$AL$6:$AL$35,'Zaman'!G9)),IF(Girdiler!$C$8="P90",INDEX(Python_girdileri!$AD$6:$AD$35,'Zaman'!G9),INDEX(Python_girdileri!$V$6:$V$35,'Zaman'!G9))),IF(Girdiler!$C$8="P90",INDEX(Python_girdileri!$N$6:$N$35,'Zaman'!G9),INDEX(Python_girdileri!$F$6:$F$35,'Zaman'!G9))),0) | H9: =IF('Zaman'!H13=1,IF(Girdiler!$C$91=1,IF('Zaman'!H15=1,IF(Girdiler!$C$8="P90",INDEX(Python_girdileri!$AT$6:$AT$35,'Zaman'!H9),INDEX(Python_girdileri!$AL$6:$AL$35,'Zaman'!H9)),IF(Girdiler!$C$8="P90",INDEX(Python_girdileri!$AD$6:$AD$35,'Zaman'!H9),INDEX(Python_girdileri!$V$6:$V$35,'Zaman'!H9))),IF(Girdiler!$C$8="P90",INDEX(Python_girdileri!$N$6:$N$35,'Zaman'!H9),INDEX(Python_girdileri!$F$6:$F$35,'Zaman'!H9))),0) | I9: =IF('Zaman'!I13=1,IF(Girdiler!$C$91=1,IF('Zaman'!I15=1,IF(Girdiler!$C$8="P90",INDEX(Python_girdileri!$AT$6:$AT$35,'Zaman'!I9),INDEX(Python_girdileri!$AL$6:$AL$35,'Zaman'!I9)),IF(Girdiler!$C$8="P90",INDEX(Python_girdileri!$AD$6:$AD$35,'Zaman'!I9),INDEX(Python_girdileri!$V$6:$V$35,'Zaman'!I9))),IF(Girdiler!$C$8="P90",INDEX(Python_girdileri!$N$6:$N$35,'Zaman'!I9),INDEX(Python_girdileri!$F$6:$F$35,'Zaman'!I9))),0) | J9: =IF('Zaman'!J13=1,IF(Girdiler!$C$91=1,IF('Zaman'!J15=1,IF(Girdiler!$C$8="P90",INDEX(Python_girdileri!$AT$6:$AT$35,'Zaman'!J9),INDEX(Python_girdileri!$AL$6:$AL$35,'Zaman'!J9)),IF(Girdiler!$C$8="P90",INDEX(Python_girdileri!$AD$6:$AD$35,'Zaman'!J9),INDEX(Python_girdileri!$V$6:$V$35,'Zaman'!J9))),IF(Girdiler!$C$8="P90",INDEX(Python_girdileri!$N$6:$N$35,'Zaman'!J9),INDEX(Python_girdileri!$F$6:$F$35,'Zaman'!J9))),0) | K9: =IF('Zaman'!K13=1,IF(Girdiler!$C$91=1,IF('Zaman'!K15=1,IF(Girdiler!$C$8="P90",INDEX(Python_girdileri!$AT$6:$AT$35,'Zaman'!K9),INDEX(Python_girdileri!$AL$6:$AL$35,'Zaman'!K9)),IF(Girdiler!$C$8="P90",INDEX(Python_girdileri!$AD$6:$AD$35,'Zaman'!K9),INDEX(Python_girdileri!$V$6:$V$35,'Zaman'!K9))),IF(Girdiler!$C$8="P90",INDEX(Python_girdileri!$N$6:$N$35,'Zaman'!K9),INDEX(Python_girdileri!$F$6:$F$35,'Zaman'!K9))),0) | L9: =IF('Zaman'!L13=1,IF(Girdiler!$C$91=1,IF('Zaman'!L15=1,IF(Girdiler!$C$8="P90",INDEX(Python_girdileri!$AT$6:$AT$35,'Zaman'!L9),INDEX(Python_girdileri!$AL$6:$AL$35,'Zaman'!L9)),IF(Girdiler!$C$8="P90",INDEX(Python_girdileri!$AD$6:$AD$35,'Zaman'!L9),INDEX(Python_girdileri!$V$6:$V$35,'Zaman'!L9))),IF(Girdiler!$C$8="P90",INDEX(Python_girdileri!$N$6:$N$35,'Zaman'!L9),INDEX(Python_girdileri!$F$6:$F$35,'Zaman'!L9))),0) | M9: =IF('Zaman'!M13=1,IF(Girdiler!$C$91=1,IF('Zaman'!M15=1,IF(Girdiler!$C$8="P90",INDEX(Python_girdileri!$AT$6:$AT$35,'Zaman'!M9),INDEX(Python_girdileri!$AL$6:$AL$35,'Zaman'!M9)),IF(Girdiler!$C$8="P90",INDEX(Python_girdileri!$AD$6:$AD$35,'Zaman'!M9),INDEX(Python_girdileri!$V$6:$V$35,'Zaman'!M9))),IF(Girdiler!$C$8="P90",INDEX(Python_girdileri!$N$6:$N$35,'Zaman'!M9),INDEX(Python_girdileri!$F$6:$F$35,'Zaman'!M9))),0) | ... AR9: =IF('Zaman'!AR13=1,IF(Girdiler!$C$91=1,IF('Zaman'!AR15=1,IF(Girdiler!$C$8="P90",INDEX(Python_girdileri!$AT$6:$AT$35,'Zaman'!AR9),INDEX(Python_girdileri!$AL$6:$AL$35,'Zaman'!AR9)),IF(Girdiler!$C$8="P90",INDEX(Python_girdileri!$AD$6:$AD$35,'Zaman'!AR9),INDEX(Python_girdileri!$V$6:$V$35,'Zaman'!AR9))),IF(Girdiler!$C$8="P90",INDEX(Python_girdileri!$N$6:$N$35,'Zaman'!AR9),INDEX(Python_girdileri!$F$6:$F$35,'Zaman'!AR9))),0)
A10: gelir_d_q | B10: birim | C10: Python_girdileri (rejim: katılıma göre Y1/Y0, aksi T) | D10: =SUM(F10:AR10) | E10: 0 | F10: =IF('Zaman'!F13=1,IF(Girdiler!$C$91=1,IF('Zaman'!F15=1,IF(Girdiler!$C$8="P90",INDEX(Python_girdileri!$AU$6:$AU$35,'Zaman'!F9),INDEX(Python_girdileri!$AM$6:$AM$35,'Zaman'!F9)),IF(Girdiler!$C$8="P90",INDEX(Python_girdileri!$AE$6:$AE$35,'Zaman'!F9),INDEX(Python_girdileri!$W$6:$W$35,'Zaman'!F9))),IF(Girdiler!$C$8="P90",INDEX(Python_girdileri!$O$6:$O$35,'Zaman'!F9),INDEX(Python_girdileri!$G$6:$G$35,'Zaman'!F9))),0) | G10: =IF('Zaman'!G13=1,IF(Girdiler!$C$91=1,IF('Zaman'!G15=1,IF(Girdiler!$C$8="P90",INDEX(Python_girdileri!$AU$6:$AU$35,'Zaman'!G9),INDEX(Python_girdileri!$AM$6:$AM$35,'Zaman'!G9)),IF(Girdiler!$C$8="P90",INDEX(Python_girdileri!$AE$6:$AE$35,'Zaman'!G9),INDEX(Python_girdileri!$W$6:$W$35,'Zaman'!G9))),IF(Girdiler!$C$8="P90",INDEX(Python_girdileri!$O$6:$O$35,'Zaman'!G9),INDEX(Python_girdileri!$G$6:$G$35,'Zaman'!G9))),0) | H10: =IF('Zaman'!H13=1,IF(Girdiler!$C$91=1,IF('Zaman'!H15=1,IF(Girdiler!$C$8="P90",INDEX(Python_girdileri!$AU$6:$AU$35,'Zaman'!H9),INDEX(Python_girdileri!$AM$6:$AM$35,'Zaman'!H9)),IF(Girdiler!$C$8="P90",INDEX(Python_girdileri!$AE$6:$AE$35,'Zaman'!H9),INDEX(Python_girdileri!$W$6:$W$35,'Zaman'!H9))),IF(Girdiler!$C$8="P90",INDEX(Python_girdileri!$O$6:$O$35,'Zaman'!H9),INDEX(Python_girdileri!$G$6:$G$35,'Zaman'!H9))),0) | I10: =IF('Zaman'!I13=1,IF(Girdiler!$C$91=1,IF('Zaman'!I15=1,IF(Girdiler!$C$8="P90",INDEX(Python_girdileri!$AU$6:$AU$35,'Zaman'!I9),INDEX(Python_girdileri!$AM$6:$AM$35,'Zaman'!I9)),IF(Girdiler!$C$8="P90",INDEX(Python_girdileri!$AE$6:$AE$35,'Zaman'!I9),INDEX(Python_girdileri!$W$6:$W$35,'Zaman'!I9))),IF(Girdiler!$C$8="P90",INDEX(Python_girdileri!$O$6:$O$35,'Zaman'!I9),INDEX(Python_girdileri!$G$6:$G$35,'Zaman'!I9))),0) | J10: =IF('Zaman'!J13=1,IF(Girdiler!$C$91=1,IF('Zaman'!J15=1,IF(Girdiler!$C$8="P90",INDEX(Python_girdileri!$AU$6:$AU$35,'Zaman'!J9),INDEX(Python_girdileri!$AM$6:$AM$35,'Zaman'!J9)),IF(Girdiler!$C$8="P90",INDEX(Python_girdileri!$AE$6:$AE$35,'Zaman'!J9),INDEX(Python_girdileri!$W$6:$W$35,'Zaman'!J9))),IF(Girdiler!$C$8="P90",INDEX(Python_girdileri!$O$6:$O$35,'Zaman'!J9),INDEX(Python_girdileri!$G$6:$G$35,'Zaman'!J9))),0) | K10: =IF('Zaman'!K13=1,IF(Girdiler!$C$91=1,IF('Zaman'!K15=1,IF(Girdiler!$C$8="P90",INDEX(Python_girdileri!$AU$6:$AU$35,'Zaman'!K9),INDEX(Python_girdileri!$AM$6:$AM$35,'Zaman'!K9)),IF(Girdiler!$C$8="P90",INDEX(Python_girdileri!$AE$6:$AE$35,'Zaman'!K9),INDEX(Python_girdileri!$W$6:$W$35,'Zaman'!K9))),IF(Girdiler!$C$8="P90",INDEX(Python_girdileri!$O$6:$O$35,'Zaman'!K9),INDEX(Python_girdileri!$G$6:$G$35,'Zaman'!K9))),0) | L10: =IF('Zaman'!L13=1,IF(Girdiler!$C$91=1,IF('Zaman'!L15=1,IF(Girdiler!$C$8="P90",INDEX(Python_girdileri!$AU$6:$AU$35,'Zaman'!L9),INDEX(Python_girdileri!$AM$6:$AM$35,'Zaman'!L9)),IF(Girdiler!$C$8="P90",INDEX(Python_girdileri!$AE$6:$AE$35,'Zaman'!L9),INDEX(Python_girdileri!$W$6:$W$35,'Zaman'!L9))),IF(Girdiler!$C$8="P90",INDEX(Python_girdileri!$O$6:$O$35,'Zaman'!L9),INDEX(Python_girdileri!$G$6:$G$35,'Zaman'!L9))),0) | M10: =IF('Zaman'!M13=1,IF(Girdiler!$C$91=1,IF('Zaman'!M15=1,IF(Girdiler!$C$8="P90",INDEX(Python_girdileri!$AU$6:$AU$35,'Zaman'!M9),INDEX(Python_girdileri!$AM$6:$AM$35,'Zaman'!M9)),IF(Girdiler!$C$8="P90",INDEX(Python_girdileri!$AE$6:$AE$35,'Zaman'!M9),INDEX(Python_girdileri!$W$6:$W$35,'Zaman'!M9))),IF(Girdiler!$C$8="P90",INDEX(Python_girdileri!$O$6:$O$35,'Zaman'!M9),INDEX(Python_girdileri!$G$6:$G$35,'Zaman'!M9))),0) | ... AR10: =IF('Zaman'!AR13=1,IF(Girdiler!$C$91=1,IF('Zaman'!AR15=1,IF(Girdiler!$C$8="P90",INDEX(Python_girdileri!$AU$6:$AU$35,'Zaman'!AR9),INDEX(Python_girdileri!$AM$6:$AM$35,'Zaman'!AR9)),IF(Girdiler!$C$8="P90",INDEX(Python_girdileri!$AE$6:$AE$35,'Zaman'!AR9),INDEX(Python_girdileri!$W$6:$W$35,'Zaman'!AR9))),IF(Girdiler!$C$8="P90",INDEX(Python_girdileri!$O$6:$O$35,'Zaman'!AR9),INDEX(Python_girdileri!$G$6:$G$35,'Zaman'!AR9))),0)
A11: E_d | B11: MWh | C11: Python_girdileri (rejim: katılıma göre Y1/Y0, aksi T) | D11: =SUM(F11:AR11) | E11: 0 | F11: =IF('Zaman'!F13=1,IF(Girdiler!$C$91=1,IF('Zaman'!F15=1,IF(Girdiler!$C$8="P90",INDEX(Python_girdileri!$AV$6:$AV$35,'Zaman'!F9),INDEX(Python_girdileri!$AN$6:$AN$35,'Zaman'!F9)),IF(Girdiler!$C$8="P90",INDEX(Python_girdileri!$AF$6:$AF$35,'Zaman'!F9),INDEX(Python_girdileri!$X$6:$X$35,'Zaman'!F9))),IF(Girdiler!$C$8="P90",INDEX(Python_girdileri!$P$6:$P$35,'Zaman'!F9),INDEX(Python_girdileri!$H$6:$H$35,'Zaman'!F9))),0) | G11: =IF('Zaman'!G13=1,IF(Girdiler!$C$91=1,IF('Zaman'!G15=1,IF(Girdiler!$C$8="P90",INDEX(Python_girdileri!$AV$6:$AV$35,'Zaman'!G9),INDEX(Python_girdileri!$AN$6:$AN$35,'Zaman'!G9)),IF(Girdiler!$C$8="P90",INDEX(Python_girdileri!$AF$6:$AF$35,'Zaman'!G9),INDEX(Python_girdileri!$X$6:$X$35,'Zaman'!G9))),IF(Girdiler!$C$8="P90",INDEX(Python_girdileri!$P$6:$P$35,'Zaman'!G9),INDEX(Python_girdileri!$H$6:$H$35,'Zaman'!G9))),0) | H11: =IF('Zaman'!H13=1,IF(Girdiler!$C$91=1,IF('Zaman'!H15=1,IF(Girdiler!$C$8="P90",INDEX(Python_girdileri!$AV$6:$AV$35,'Zaman'!H9),INDEX(Python_girdileri!$AN$6:$AN$35,'Zaman'!H9)),IF(Girdiler!$C$8="P90",INDEX(Python_girdileri!$AF$6:$AF$35,'Zaman'!H9),INDEX(Python_girdileri!$X$6:$X$35,'Zaman'!H9))),IF(Girdiler!$C$8="P90",INDEX(Python_girdileri!$P$6:$P$35,'Zaman'!H9),INDEX(Python_girdileri!$H$6:$H$35,'Zaman'!H9))),0) | I11: =IF('Zaman'!I13=1,IF(Girdiler!$C$91=1,IF('Zaman'!I15=1,IF(Girdiler!$C$8="P90",INDEX(Python_girdileri!$AV$6:$AV$35,'Zaman'!I9),INDEX(Python_girdileri!$AN$6:$AN$35,'Zaman'!I9)),IF(Girdiler!$C$8="P90",INDEX(Python_girdileri!$AF$6:$AF$35,'Zaman'!I9),INDEX(Python_girdileri!$X$6:$X$35,'Zaman'!I9))),IF(Girdiler!$C$8="P90",INDEX(Python_girdileri!$P$6:$P$35,'Zaman'!I9),INDEX(Python_girdileri!$H$6:$H$35,'Zaman'!I9))),0) | J11: =IF('Zaman'!J13=1,IF(Girdiler!$C$91=1,IF('Zaman'!J15=1,IF(Girdiler!$C$8="P90",INDEX(Python_girdileri!$AV$6:$AV$35,'Zaman'!J9),INDEX(Python_girdileri!$AN$6:$AN$35,'Zaman'!J9)),IF(Girdiler!$C$8="P90",INDEX(Python_girdileri!$AF$6:$AF$35,'Zaman'!J9),INDEX(Python_girdileri!$X$6:$X$35,'Zaman'!J9))),IF(Girdiler!$C$8="P90",INDEX(Python_girdileri!$P$6:$P$35,'Zaman'!J9),INDEX(Python_girdileri!$H$6:$H$35,'Zaman'!J9))),0) | K11: =IF('Zaman'!K13=1,IF(Girdiler!$C$91=1,IF('Zaman'!K15=1,IF(Girdiler!$C$8="P90",INDEX(Python_girdileri!$AV$6:$AV$35,'Zaman'!K9),INDEX(Python_girdileri!$AN$6:$AN$35,'Zaman'!K9)),IF(Girdiler!$C$8="P90",INDEX(Python_girdileri!$AF$6:$AF$35,'Zaman'!K9),INDEX(Python_girdileri!$X$6:$X$35,'Zaman'!K9))),IF(Girdiler!$C$8="P90",INDEX(Python_girdileri!$P$6:$P$35,'Zaman'!K9),INDEX(Python_girdileri!$H$6:$H$35,'Zaman'!K9))),0) | L11: =IF('Zaman'!L13=1,IF(Girdiler!$C$91=1,IF('Zaman'!L15=1,IF(Girdiler!$C$8="P90",INDEX(Python_girdileri!$AV$6:$AV$35,'Zaman'!L9),INDEX(Python_girdileri!$AN$6:$AN$35,'Zaman'!L9)),IF(Girdiler!$C$8="P90",INDEX(Python_girdileri!$AF$6:$AF$35,'Zaman'!L9),INDEX(Python_girdileri!$X$6:$X$35,'Zaman'!L9))),IF(Girdiler!$C$8="P90",INDEX(Python_girdileri!$P$6:$P$35,'Zaman'!L9),INDEX(Python_girdileri!$H$6:$H$35,'Zaman'!L9))),0) | M11: =IF('Zaman'!M13=1,IF(Girdiler!$C$91=1,IF('Zaman'!M15=1,IF(Girdiler!$C$8="P90",INDEX(Python_girdileri!$AV$6:$AV$35,'Zaman'!M9),INDEX(Python_girdileri!$AN$6:$AN$35,'Zaman'!M9)),IF(Girdiler!$C$8="P90",INDEX(Python_girdileri!$AF$6:$AF$35,'Zaman'!M9),INDEX(Python_girdileri!$X$6:$X$35,'Zaman'!M9))),IF(Girdiler!$C$8="P90",INDEX(Python_girdileri!$P$6:$P$35,'Zaman'!M9),INDEX(Python_girdileri!$H$6:$H$35,'Zaman'!M9))),0) | ... AR11: =IF('Zaman'!AR13=1,IF(Girdiler!$C$91=1,IF('Zaman'!AR15=1,IF(Girdiler!$C$8="P90",INDEX(Python_girdileri!$AV$6:$AV$35,'Zaman'!AR9),INDEX(Python_girdileri!$AN$6:$AN$35,'Zaman'!AR9)),IF(Girdiler!$C$8="P90",INDEX(Python_girdileri!$AF$6:$AF$35,'Zaman'!AR9),INDEX(Python_girdileri!$X$6:$X$35,'Zaman'!AR9))),IF(Girdiler!$C$8="P90",INDEX(Python_girdileri!$P$6:$P$35,'Zaman'!AR9),INDEX(Python_girdileri!$H$6:$H$35,'Zaman'!AR9))),0)
A12: yh_a | B12: birim | C12: Python_girdileri (rejim: katılıma göre Y1/Y0, aksi T) | D12: =SUM(F12:AR12) | E12: 0 | F12: =IF('Zaman'!F13=1,IF(Girdiler!$C$91=1,IF('Zaman'!F15=1,IF(Girdiler!$C$8="P90",INDEX(Python_girdileri!$AW$6:$AW$35,'Zaman'!F9),INDEX(Python_girdileri!$AO$6:$AO$35,'Zaman'!F9)),IF(Girdiler!$C$8="P90",INDEX(Python_girdileri!$AG$6:$AG$35,'Zaman'!F9),INDEX(Python_girdileri!$Y$6:$Y$35,'Zaman'!F9))),IF(Girdiler!$C$8="P90",INDEX(Python_girdileri!$Q$6:$Q$35,'Zaman'!F9),INDEX(Python_girdileri!$I$6:$I$35,'Zaman'!F9))),0) | G12: =IF('Zaman'!G13=1,IF(Girdiler!$C$91=1,IF('Zaman'!G15=1,IF(Girdiler!$C$8="P90",INDEX(Python_girdileri!$AW$6:$AW$35,'Zaman'!G9),INDEX(Python_girdileri!$AO$6:$AO$35,'Zaman'!G9)),IF(Girdiler!$C$8="P90",INDEX(Python_girdileri!$AG$6:$AG$35,'Zaman'!G9),INDEX(Python_girdileri!$Y$6:$Y$35,'Zaman'!G9))),IF(Girdiler!$C$8="P90",INDEX(Python_girdileri!$Q$6:$Q$35,'Zaman'!G9),INDEX(Python_girdileri!$I$6:$I$35,'Zaman'!G9))),0) | H12: =IF('Zaman'!H13=1,IF(Girdiler!$C$91=1,IF('Zaman'!H15=1,IF(Girdiler!$C$8="P90",INDEX(Python_girdileri!$AW$6:$AW$35,'Zaman'!H9),INDEX(Python_girdileri!$AO$6:$AO$35,'Zaman'!H9)),IF(Girdiler!$C$8="P90",INDEX(Python_girdileri!$AG$6:$AG$35,'Zaman'!H9),INDEX(Python_girdileri!$Y$6:$Y$35,'Zaman'!H9))),IF(Girdiler!$C$8="P90",INDEX(Python_girdileri!$Q$6:$Q$35,'Zaman'!H9),INDEX(Python_girdileri!$I$6:$I$35,'Zaman'!H9))),0) | I12: =IF('Zaman'!I13=1,IF(Girdiler!$C$91=1,IF('Zaman'!I15=1,IF(Girdiler!$C$8="P90",INDEX(Python_girdileri!$AW$6:$AW$35,'Zaman'!I9),INDEX(Python_girdileri!$AO$6:$AO$35,'Zaman'!I9)),IF(Girdiler!$C$8="P90",INDEX(Python_girdileri!$AG$6:$AG$35,'Zaman'!I9),INDEX(Python_girdileri!$Y$6:$Y$35,'Zaman'!I9))),IF(Girdiler!$C$8="P90",INDEX(Python_girdileri!$Q$6:$Q$35,'Zaman'!I9),INDEX(Python_girdileri!$I$6:$I$35,'Zaman'!I9))),0) | J12: =IF('Zaman'!J13=1,IF(Girdiler!$C$91=1,IF('Zaman'!J15=1,IF(Girdiler!$C$8="P90",INDEX(Python_girdileri!$AW$6:$AW$35,'Zaman'!J9),INDEX(Python_girdileri!$AO$6:$AO$35,'Zaman'!J9)),IF(Girdiler!$C$8="P90",INDEX(Python_girdileri!$AG$6:$AG$35,'Zaman'!J9),INDEX(Python_girdileri!$Y$6:$Y$35,'Zaman'!J9))),IF(Girdiler!$C$8="P90",INDEX(Python_girdileri!$Q$6:$Q$35,'Zaman'!J9),INDEX(Python_girdileri!$I$6:$I$35,'Zaman'!J9))),0) | K12: =IF('Zaman'!K13=1,IF(Girdiler!$C$91=1,IF('Zaman'!K15=1,IF(Girdiler!$C$8="P90",INDEX(Python_girdileri!$AW$6:$AW$35,'Zaman'!K9),INDEX(Python_girdileri!$AO$6:$AO$35,'Zaman'!K9)),IF(Girdiler!$C$8="P90",INDEX(Python_girdileri!$AG$6:$AG$35,'Zaman'!K9),INDEX(Python_girdileri!$Y$6:$Y$35,'Zaman'!K9))),IF(Girdiler!$C$8="P90",INDEX(Python_girdileri!$Q$6:$Q$35,'Zaman'!K9),INDEX(Python_girdileri!$I$6:$I$35,'Zaman'!K9))),0) | L12: =IF('Zaman'!L13=1,IF(Girdiler!$C$91=1,IF('Zaman'!L15=1,IF(Girdiler!$C$8="P90",INDEX(Python_girdileri!$AW$6:$AW$35,'Zaman'!L9),INDEX(Python_girdileri!$AO$6:$AO$35,'Zaman'!L9)),IF(Girdiler!$C$8="P90",INDEX(Python_girdileri!$AG$6:$AG$35,'Zaman'!L9),INDEX(Python_girdileri!$Y$6:$Y$35,'Zaman'!L9))),IF(Girdiler!$C$8="P90",INDEX(Python_girdileri!$Q$6:$Q$35,'Zaman'!L9),INDEX(Python_girdileri!$I$6:$I$35,'Zaman'!L9))),0) | M12: =IF('Zaman'!M13=1,IF(Girdiler!$C$91=1,IF('Zaman'!M15=1,IF(Girdiler!$C$8="P90",INDEX(Python_girdileri!$AW$6:$AW$35,'Zaman'!M9),INDEX(Python_girdileri!$AO$6:$AO$35,'Zaman'!M9)),IF(Girdiler!$C$8="P90",INDEX(Python_girdileri!$AG$6:$AG$35,'Zaman'!M9),INDEX(Python_girdileri!$Y$6:$Y$35,'Zaman'!M9))),IF(Girdiler!$C$8="P90",INDEX(Python_girdileri!$Q$6:$Q$35,'Zaman'!M9),INDEX(Python_girdileri!$I$6:$I$35,'Zaman'!M9))),0) | ... AR12: =IF('Zaman'!AR13=1,IF(Girdiler!$C$91=1,IF('Zaman'!AR15=1,IF(Girdiler!$C$8="P90",INDEX(Python_girdileri!$AW$6:$AW$35,'Zaman'!AR9),INDEX(Python_girdileri!$AO$6:$AO$35,'Zaman'!AR9)),IF(Girdiler!$C$8="P90",INDEX(Python_girdileri!$AG$6:$AG$35,'Zaman'!AR9),INDEX(Python_girdileri!$Y$6:$Y$35,'Zaman'!AR9))),IF(Girdiler!$C$8="P90",INDEX(Python_girdileri!$Q$6:$Q$35,'Zaman'!AR9),INDEX(Python_girdileri!$I$6:$I$35,'Zaman'!AR9))),0)
A13: rezerv | B13: MWh | C13: Python_girdileri (rejim: katılıma göre Y1/Y0, aksi T) | D13: =SUM(F13:AR13) | E13: 0 | F13: =IF('Zaman'!F13=1,IF(Girdiler!$C$91=1,IF('Zaman'!F15=1,IF(Girdiler!$C$8="P90",INDEX(Python_girdileri!$AX$6:$AX$35,'Zaman'!F9),INDEX(Python_girdileri!$AP$6:$AP$35,'Zaman'!F9)),IF(Girdiler!$C$8="P90",INDEX(Python_girdileri!$AH$6:$AH$35,'Zaman'!F9),INDEX(Python_girdileri!$Z$6:$Z$35,'Zaman'!F9))),IF(Girdiler!$C$8="P90",INDEX(Python_girdileri!$R$6:$R$35,'Zaman'!F9),INDEX(Python_girdileri!$J$6:$J$35,'Zaman'!F9))),0) | G13: =IF('Zaman'!G13=1,IF(Girdiler!$C$91=1,IF('Zaman'!G15=1,IF(Girdiler!$C$8="P90",INDEX(Python_girdileri!$AX$6:$AX$35,'Zaman'!G9),INDEX(Python_girdileri!$AP$6:$AP$35,'Zaman'!G9)),IF(Girdiler!$C$8="P90",INDEX(Python_girdileri!$AH$6:$AH$35,'Zaman'!G9),INDEX(Python_girdileri!$Z$6:$Z$35,'Zaman'!G9))),IF(Girdiler!$C$8="P90",INDEX(Python_girdileri!$R$6:$R$35,'Zaman'!G9),INDEX(Python_girdileri!$J$6:$J$35,'Zaman'!G9))),0) | H13: =IF('Zaman'!H13=1,IF(Girdiler!$C$91=1,IF('Zaman'!H15=1,IF(Girdiler!$C$8="P90",INDEX(Python_girdileri!$AX$6:$AX$35,'Zaman'!H9),INDEX(Python_girdileri!$AP$6:$AP$35,'Zaman'!H9)),IF(Girdiler!$C$8="P90",INDEX(Python_girdileri!$AH$6:$AH$35,'Zaman'!H9),INDEX(Python_girdileri!$Z$6:$Z$35,'Zaman'!H9))),IF(Girdiler!$C$8="P90",INDEX(Python_girdileri!$R$6:$R$35,'Zaman'!H9),INDEX(Python_girdileri!$J$6:$J$35,'Zaman'!H9))),0) | I13: =IF('Zaman'!I13=1,IF(Girdiler!$C$91=1,IF('Zaman'!I15=1,IF(Girdiler!$C$8="P90",INDEX(Python_girdileri!$AX$6:$AX$35,'Zaman'!I9),INDEX(Python_girdileri!$AP$6:$AP$35,'Zaman'!I9)),IF(Girdiler!$C$8="P90",INDEX(Python_girdileri!$AH$6:$AH$35,'Zaman'!I9),INDEX(Python_girdileri!$Z$6:$Z$35,'Zaman'!I9))),IF(Girdiler!$C$8="P90",INDEX(Python_girdileri!$R$6:$R$35,'Zaman'!I9),INDEX(Python_girdileri!$J$6:$J$35,'Zaman'!I9))),0) | J13: =IF('Zaman'!J13=1,IF(Girdiler!$C$91=1,IF('Zaman'!J15=1,IF(Girdiler!$C$8="P90",INDEX(Python_girdileri!$AX$6:$AX$35,'Zaman'!J9),INDEX(Python_girdileri!$AP$6:$AP$35,'Zaman'!J9)),IF(Girdiler!$C$8="P90",INDEX(Python_girdileri!$AH$6:$AH$35,'Zaman'!J9),INDEX(Python_girdileri!$Z$6:$Z$35,'Zaman'!J9))),IF(Girdiler!$C$8="P90",INDEX(Python_girdileri!$R$6:$R$35,'Zaman'!J9),INDEX(Python_girdileri!$J$6:$J$35,'Zaman'!J9))),0) | K13: =IF('Zaman'!K13=1,IF(Girdiler!$C$91=1,IF('Zaman'!K15=1,IF(Girdiler!$C$8="P90",INDEX(Python_girdileri!$AX$6:$AX$35,'Zaman'!K9),INDEX(Python_girdileri!$AP$6:$AP$35,'Zaman'!K9)),IF(Girdiler!$C$8="P90",INDEX(Python_girdileri!$AH$6:$AH$35,'Zaman'!K9),INDEX(Python_girdileri!$Z$6:$Z$35,'Zaman'!K9))),IF(Girdiler!$C$8="P90",INDEX(Python_girdileri!$R$6:$R$35,'Zaman'!K9),INDEX(Python_girdileri!$J$6:$J$35,'Zaman'!K9))),0) | L13: =IF('Zaman'!L13=1,IF(Girdiler!$C$91=1,IF('Zaman'!L15=1,IF(Girdiler!$C$8="P90",INDEX(Python_girdileri!$AX$6:$AX$35,'Zaman'!L9),INDEX(Python_girdileri!$AP$6:$AP$35,'Zaman'!L9)),IF(Girdiler!$C$8="P90",INDEX(Python_girdileri!$AH$6:$AH$35,'Zaman'!L9),INDEX(Python_girdileri!$Z$6:$Z$35,'Zaman'!L9))),IF(Girdiler!$C$8="P90",INDEX(Python_girdileri!$R$6:$R$35,'Zaman'!L9),INDEX(Python_girdileri!$J$6:$J$35,'Zaman'!L9))),0) | M13: =IF('Zaman'!M13=1,IF(Girdiler!$C$91=1,IF('Zaman'!M15=1,IF(Girdiler!$C$8="P90",INDEX(Python_girdileri!$AX$6:$AX$35,'Zaman'!M9),INDEX(Python_girdileri!$AP$6:$AP$35,'Zaman'!M9)),IF(Girdiler!$C$8="P90",INDEX(Python_girdileri!$AH$6:$AH$35,'Zaman'!M9),INDEX(Python_girdileri!$Z$6:$Z$35,'Zaman'!M9))),IF(Girdiler!$C$8="P90",INDEX(Python_girdileri!$R$6:$R$35,'Zaman'!M9),INDEX(Python_girdileri!$J$6:$J$35,'Zaman'!M9))),0) | ... AR13: =IF('Zaman'!AR13=1,IF(Girdiler!$C$91=1,IF('Zaman'!AR15=1,IF(Girdiler!$C$8="P90",INDEX(Python_girdileri!$AX$6:$AX$35,'Zaman'!AR9),INDEX(Python_girdileri!$AP$6:$AP$35,'Zaman'!AR9)),IF(Girdiler!$C$8="P90",INDEX(Python_girdileri!$AH$6:$AH$35,'Zaman'!AR9),INDEX(Python_girdileri!$Z$6:$Z$35,'Zaman'!AR9))),IF(Girdiler!$C$8="P90",INDEX(Python_girdileri!$R$6:$R$35,'Zaman'!AR9),INDEX(Python_girdileri!$J$6:$J$35,'Zaman'!AR9))),0)
A14: E_k | B14: MWh | C14: Python_girdileri (rejim: katılıma göre Y1/Y0, aksi T) | D14: =SUM(F14:AR14) | E14: 0 | F14: =IF('Zaman'!F13=1,IF(Girdiler!$C$91=1,IF('Zaman'!F15=1,IF(Girdiler!$C$8="P90",INDEX(Python_girdileri!$AY$6:$AY$35,'Zaman'!F9),INDEX(Python_girdileri!$AQ$6:$AQ$35,'Zaman'!F9)),IF(Girdiler!$C$8="P90",INDEX(Python_girdileri!$AI$6:$AI$35,'Zaman'!F9),INDEX(Python_girdileri!$AA$6:$AA$35,'Zaman'!F9))),IF(Girdiler!$C$8="P90",INDEX(Python_girdileri!$S$6:$S$35,'Zaman'!F9),INDEX(Python_girdileri!$K$6:$K$35,'Zaman'!F9))),0) | G14: =IF('Zaman'!G13=1,IF(Girdiler!$C$91=1,IF('Zaman'!G15=1,IF(Girdiler!$C$8="P90",INDEX(Python_girdileri!$AY$6:$AY$35,'Zaman'!G9),INDEX(Python_girdileri!$AQ$6:$AQ$35,'Zaman'!G9)),IF(Girdiler!$C$8="P90",INDEX(Python_girdileri!$AI$6:$AI$35,'Zaman'!G9),INDEX(Python_girdileri!$AA$6:$AA$35,'Zaman'!G9))),IF(Girdiler!$C$8="P90",INDEX(Python_girdileri!$S$6:$S$35,'Zaman'!G9),INDEX(Python_girdileri!$K$6:$K$35,'Zaman'!G9))),0) | H14: =IF('Zaman'!H13=1,IF(Girdiler!$C$91=1,IF('Zaman'!H15=1,IF(Girdiler!$C$8="P90",INDEX(Python_girdileri!$AY$6:$AY$35,'Zaman'!H9),INDEX(Python_girdileri!$AQ$6:$AQ$35,'Zaman'!H9)),IF(Girdiler!$C$8="P90",INDEX(Python_girdileri!$AI$6:$AI$35,'Zaman'!H9),INDEX(Python_girdileri!$AA$6:$AA$35,'Zaman'!H9))),IF(Girdiler!$C$8="P90",INDEX(Python_girdileri!$S$6:$S$35,'Zaman'!H9),INDEX(Python_girdileri!$K$6:$K$35,'Zaman'!H9))),0) | I14: =IF('Zaman'!I13=1,IF(Girdiler!$C$91=1,IF('Zaman'!I15=1,IF(Girdiler!$C$8="P90",INDEX(Python_girdileri!$AY$6:$AY$35,'Zaman'!I9),INDEX(Python_girdileri!$AQ$6:$AQ$35,'Zaman'!I9)),IF(Girdiler!$C$8="P90",INDEX(Python_girdileri!$AI$6:$AI$35,'Zaman'!I9),INDEX(Python_girdileri!$AA$6:$AA$35,'Zaman'!I9))),IF(Girdiler!$C$8="P90",INDEX(Python_girdileri!$S$6:$S$35,'Zaman'!I9),INDEX(Python_girdileri!$K$6:$K$35,'Zaman'!I9))),0) | J14: =IF('Zaman'!J13=1,IF(Girdiler!$C$91=1,IF('Zaman'!J15=1,IF(Girdiler!$C$8="P90",INDEX(Python_girdileri!$AY$6:$AY$35,'Zaman'!J9),INDEX(Python_girdileri!$AQ$6:$AQ$35,'Zaman'!J9)),IF(Girdiler!$C$8="P90",INDEX(Python_girdileri!$AI$6:$AI$35,'Zaman'!J9),INDEX(Python_girdileri!$AA$6:$AA$35,'Zaman'!J9))),IF(Girdiler!$C$8="P90",INDEX(Python_girdileri!$S$6:$S$35,'Zaman'!J9),INDEX(Python_girdileri!$K$6:$K$35,'Zaman'!J9))),0) | K14: =IF('Zaman'!K13=1,IF(Girdiler!$C$91=1,IF('Zaman'!K15=1,IF(Girdiler!$C$8="P90",INDEX(Python_girdileri!$AY$6:$AY$35,'Zaman'!K9),INDEX(Python_girdileri!$AQ$6:$AQ$35,'Zaman'!K9)),IF(Girdiler!$C$8="P90",INDEX(Python_girdileri!$AI$6:$AI$35,'Zaman'!K9),INDEX(Python_girdileri!$AA$6:$AA$35,'Zaman'!K9))),IF(Girdiler!$C$8="P90",INDEX(Python_girdileri!$S$6:$S$35,'Zaman'!K9),INDEX(Python_girdileri!$K$6:$K$35,'Zaman'!K9))),0) | L14: =IF('Zaman'!L13=1,IF(Girdiler!$C$91=1,IF('Zaman'!L15=1,IF(Girdiler!$C$8="P90",INDEX(Python_girdileri!$AY$6:$AY$35,'Zaman'!L9),INDEX(Python_girdileri!$AQ$6:$AQ$35,'Zaman'!L9)),IF(Girdiler!$C$8="P90",INDEX(Python_girdileri!$AI$6:$AI$35,'Zaman'!L9),INDEX(Python_girdileri!$AA$6:$AA$35,'Zaman'!L9))),IF(Girdiler!$C$8="P90",INDEX(Python_girdileri!$S$6:$S$35,'Zaman'!L9),INDEX(Python_girdileri!$K$6:$K$35,'Zaman'!L9))),0) | M14: =IF('Zaman'!M13=1,IF(Girdiler!$C$91=1,IF('Zaman'!M15=1,IF(Girdiler!$C$8="P90",INDEX(Python_girdileri!$AY$6:$AY$35,'Zaman'!M9),INDEX(Python_girdileri!$AQ$6:$AQ$35,'Zaman'!M9)),IF(Girdiler!$C$8="P90",INDEX(Python_girdileri!$AI$6:$AI$35,'Zaman'!M9),INDEX(Python_girdileri!$AA$6:$AA$35,'Zaman'!M9))),IF(Girdiler!$C$8="P90",INDEX(Python_girdileri!$S$6:$S$35,'Zaman'!M9),INDEX(Python_girdileri!$K$6:$K$35,'Zaman'!M9))),0) | ... AR14: =IF('Zaman'!AR13=1,IF(Girdiler!$C$91=1,IF('Zaman'!AR15=1,IF(Girdiler!$C$8="P90",INDEX(Python_girdileri!$AY$6:$AY$35,'Zaman'!AR9),INDEX(Python_girdileri!$AQ$6:$AQ$35,'Zaman'!AR9)),IF(Girdiler!$C$8="P90",INDEX(Python_girdileri!$AI$6:$AI$35,'Zaman'!AR9),INDEX(Python_girdileri!$AA$6:$AA$35,'Zaman'!AR9))),IF(Girdiler!$C$8="P90",INDEX(Python_girdileri!$S$6:$S$35,'Zaman'!AR9),INDEX(Python_girdileri!$K$6:$K$35,'Zaman'!AR9))),0)
